<robot name="JueyingL3">
  <link name="dummy"></link>
  <joint name="dummy_joint" type="fixed">
    <parent link="dummy"/>
    <child link="urdf_link"/>
  </joint>
  <link name="urdf_link">
    <inertial>
      <origin xyz="0.005 0.000413 0.004" />
      <mass value="26.398" />
      <inertia ixx="0.1632" ixy="-5.2136E-05" ixz="-0.00019406" iyy="0.40648" iyz="8.2679E-05" izz="0.52596" />
    </inertial>
    <visual>
      <geometry>
        <mesh filename="package://lite3/Lite3/meshes/Torso.dae" />
      </geometry>
    </visual>
    <collision>
      <geometry>
        <box size="0.46 0.26 0.15"/>
      </geometry>
    </collision>
  </link>
  <link name="FL_HIP">
    <inertial>
      <origin xyz="-0.00075689 -0.0089129 -5.0528E-05" />
      <mass value="1.5767" />
      <inertia ixx="0.0012141" ixy="6.1989E-06" ixz="2.8652E-06" iyy="0.0016912" iyz="3.7E-06" izz="0.0013431" />
    </inertial>
    <visual>
      <geometry>
        <mesh filename="package://lite3/Lite3/meshes/FL_Hip.dae" />
      </geometry>
    </visual>
  </link>
  <joint name="LF_Joint" type="revolute">
    <origin xyz="0.292 0.08 0" />
    <parent link="urdf_link" />
    <child link="FL_HIP" />
    <axis xyz="1 0 0" />
    <limit lower="-0.523" upper="0.261" effort="30" velocity="20" />
  </joint>
  <link name="FL_THIGH">
    <inertial>
      <origin xyz="-0.0025264 -0.022118 -0.0292" />
      <mass value="3.0063" />
      <inertia ixx="0.0058102" ixy="4.2848E-05" ixz="-3.0437E-06" iyy="0.0080686" iyz="-6.889E-05" izz="0.003874" />
    </inertial>
    <visual>
      <geometry>
        <mesh filename="package://lite3/Lite3/meshes/L_Thigh.dae" />
      </geometry>
    </visual>
    <collision>
      <origin xyz="0 0 -0.13" />
      <geometry>
        <cylinder length="0.25" radius="0.04"/>
      </geometry>
    </collision>
  </link>
  <joint name="LF_Joint_1" type="revolute">
    <origin xyz="0 0.12325 0" />
    <parent link="FL_HIP" />
    <child link="FL_THIGH" />
    <axis xyz="0 1 0" />
    <limit lower="-2.53" upper="0.35" effort="40" velocity="20" />
  </joint>
  <link name="FL_SHANK">
    <inertial>
      <origin xyz="0.0075224 2.5888E-05 -0.17586" />
      <mass value="0.54849" />
      <inertia ixx="0.0057" ixy="1.16E-07" ixz="0.000153" iyy="0.006" iyz="-1.12E-06" izz="0.00029" />
    </inertial>
    <visual>
      <geometry>
        <mesh filename="package://lite3/Lite3/meshes/Shank.dae" />
      </geometry>
    </visual>
    <collision>
      <origin xyz="0.00 0 -0.33" />
      <geometry>
        <sphere radius="0.036"/>
      </geometry>
    </collision>
  </link>
  <joint name="LF_Joint_2" type="revolute">
    <origin xyz="0 0 -0.3" />
    <parent link="FL_THIGH" />
    <child link="FL_SHANK" />
    <axis xyz="0 1 0" />
    <limit lower="0.35" upper="2.53" effort="60" velocity="20" />
  </joint>
  <link name="FR_HIP">
    <inertial>
      <origin xyz="-0.000757 0.009 5.0528E-05" />
      <mass value="1.5767" />
      <inertia ixx="0.0012141" ixy="-6.1989E-06" ixz="-2.8652E-06" iyy="0.0016912" iyz="3.7E-06" izz="0.0013431" />
    </inertial>
    <visual>
      <geometry>
        <mesh filename="package://lite3/Lite3/meshes/FR_Hip.dae" />
      </geometry>
    </visual>
  </link>
  <joint name="RF_Joint" type="revolute">
    <origin xyz="0.292 -0.08 0" />
    <parent link="urdf_link" />
    <child link="FR_HIP" />
    <axis xyz="-1 0 0" />
    <limit lower="-0.523" upper="0.261" effort="30" velocity="20" />
  </joint>
  <link name="FR_THIGH">
    <inertial>
      <origin xyz="-0.0025266 0.022119 -0.029194" />
      <mass value="3.0062" />
      <inertia ixx="0.00581" ixy="-4.2781E-05" ixz="-3.0682E-06" iyy="0.0080684" iyz="6.8812E-05" izz="0.0038739" />
    </inertial>
    <visual>
      <geometry>
        <mesh filename="package://lite3/Lite3/meshes/R_Thigh.dae" />
      </geometry>
    </visual>
    <collision>
      <origin xyz="0 0 -0.13" />
      <geometry>
        <cylinder length="0.25" radius="0.04"/>
      </geometry>
    </collision>
  </link>
  <joint name="RF_Joint_1" type="revolute">
    <origin xyz="0 -0.12325 0" />
    <parent link="FR_HIP" />
    <child link="FR_THIGH" />
    <axis xyz="0 1 0" />
    <limit lower="-2.53" upper="0.35" effort="40" velocity="20" />
  </joint>
  <link name="FR_SHANK">
    <inertial>
      <origin xyz="0.0075224 2.5888E-05 -0.17586" />
      <mass value="0.54849" />
      <inertia ixx="0.0057" ixy="1.16E-07" ixz="0.000153" iyy="0.006" iyz="-1.12E-06" izz="0.00029" />
    </inertial>
    <visual>
      <geometry>
        <mesh filename="package://lite3/Lite3/meshes/Shank.dae" />
      </geometry>
    </visual>
    <collision>
      <origin xyz="0.00 0 -0.33" />
      <geometry>
        <sphere radius="0.036"/>
      </geometry>
    </collision>
  </link>
  <joint name="RF_Joint_2" type="revolute">
    <origin xyz="0 0 -0.3" />
    <parent link="FR_THIGH" />
    <child link="FR_SHANK" />
    <axis xyz="0 1 0" />
    <limit lower="0.35" upper="2.53" effort="60" velocity="20" />
  </joint>
  <link name="HL_HIP">
    <inertial>
      <origin xyz="0.000757 -0.009 5.053E-05" />
      <mass value="1.5767" />
      <inertia ixx="0.00121" ixy="-6.2E-06" ixz="2.9E-06" iyy="0.0017" iyz="-3.7E-06" izz="0.00134" />
    </inertial>
    <visual>
      <geometry>
        <mesh filename="package://lite3/Lite3/meshes/HL_Hip.dae" />
      </geometry>
    </visual>
  </link>
  <joint name="LB_Joint" type="revolute">
    <origin xyz="-0.292 0.08 0" />
    <parent link="urdf_link" />
    <child link="HL_HIP" />
    <axis xyz="1 0 0" />
    <limit lower="-0.523" upper="0.261" effort="30" velocity="20" />
  </joint>
  <link name="HL_THIGH">
    <inertial>
      <origin xyz="-0.0025264 -0.022118 -0.0292" />
      <mass value="3.0063" />
      <inertia ixx="0.0058102" ixy="4.2848E-05" ixz="-3.0433E-06" iyy="0.008" iyz="-6.8889E-05" izz="0.003874" />
    </inertial>
    <visual>
      <geometry>
        <mesh filename="package://lite3/Lite3/meshes/L_Thigh.dae" />
      </geometry>
    </visual>
    <collision>
      <origin xyz="0 0 -0.13" />
      <geometry>
        <cylinder length="0.25" radius="0.04"/>
      </geometry>
    </collision>
  </link>
  <joint name="LB_Joint_1" type="revolute">
    <origin xyz="0 0.12325 0" />
    <parent link="HL_HIP" />
    <child link="HL_THIGH" />
    <axis xyz="0 1 0" />
    <limit lower="-2.53" upper="0.35" effort="40" velocity="20" />
  </joint>
  <link name="HL_SHANK">
    <inertial>
      <origin xyz="0.0075224 2.5888E-05 -0.17586" />
      <mass value="0.54849" />
      <inertia ixx="0.0057" ixy="1.16E-07" ixz="0.000153" iyy="0.006" iyz="-1.12E-06" izz="0.00029" />
    </inertial>
    <visual>
      <geometry>
        <mesh filename="package://lite3/Lite3/meshes/Shank.dae" />
      </geometry>
    </visual>
    <collision>
      <origin xyz="0.00 0 -0.33" />
      <geometry>
        <sphere radius="0.036"/>
      </geometry>
    </collision>
  </link>
  <joint name="LB_Joint_2" type="revolute">
    <origin xyz="0 0 -0.3" />
    <parent link="HL_THIGH" />
    <child link="HL_SHANK" />
    <axis xyz="0 1 0" />
    <limit lower="0.35" upper="2.53" effort="60" velocity="20" />
  </joint>
  <link name="HR_HIP">
    <inertial>
      <origin xyz="0.00075689 0.0089129 -5.0528E-05" />
      <mass value="1.5767" />
      <inertia ixx="0.0012141" ixy="6.1989E-06" ixz="-2.8652E-06" iyy="0.0016912" iyz="-3.7E-06" izz="0.0013431" />
    </inertial>
    <visual>
      <geometry>
        <mesh filename="package://lite3/Lite3/meshes/HR_Hip.dae" />
      </geometry>
    </visual>
  </link>
  <joint name="RB_Joint" type="revolute">
    <origin xyz="-0.292 -0.08 0" />
    <parent link="urdf_link" />
    <child link="HR_HIP" />
    <axis xyz="-1 0 0" />
    <limit lower="-0.523" upper="0.261" effort="30" velocity="20" />
  </joint>
  <link name="HR_THIGH">
    <inertial>
      <origin xyz="-0.0025266 0.022119 -0.029194" />
      <mass value="3.0062" />
      <inertia ixx="0.00581" ixy="-4.2781E-05" ixz="-3.0681E-06" iyy="0.0080684" iyz="6.8812E-05" izz="0.0038739" />
    </inertial>
    <visual>
      <geometry>
        <mesh filename="package://lite3/Lite3/meshes/R_Thigh.dae" />
      </geometry>
    </visual>
    <collision>
      <origin xyz="0 0 -0.13" />
      <geometry>
        <cylinder length="0.25" radius="0.04"/>
      </geometry>
    </collision>
  </link>
  <joint name="RB_Joint_1" type="revolute">
    <origin xyz="0 -0.12325 0" />
    <parent link="HR_HIP" />
    <child link="HR_THIGH" />
    <axis xyz="0 1 0" />
    <limit lower="-2.53" upper="0.35" effort="40" velocity="20" />
  </joint>
  <link name="HR_SHANK">
    <inertial>
      <origin xyz="0.0075224 2.589E-05 -0.17586" />
      <mass value="0.54849" />
      <inertia ixx="0.0056981" ixy="1.1608E-07" ixz="0.00015292" iyy="0.0059026" iyz="-1.1243E-06" izz="0.00028822" />
    </inertial>
    <visual>
      <geometry>
        <mesh filename="package://lite3/Lite3/meshes/Shank.dae" />
      </geometry>
    </visual>
    <collision>
      <origin xyz="0.00 0 -0.33" />
      <geometry>
        <sphere radius="0.036"/>
      </geometry>
    </collision>
  </link>
  <joint name="RB_Joint_2" type="revolute">
    <origin xyz="0 0 -0.3" />
    <parent link="HR_THIGH" />
    <child link="HR_SHANK" />
    <axis xyz="0 1 0" />
    <limit lower="0.35" upper="2.53" effort="60" velocity="20" />
  </joint>
  <link name="Lidar">
    <inertial>
      <origin xyz="-0.30507 0.00041299 -0.074912" />
      <mass value="0.01" />
      <inertia ixx="0.1632" ixy="-5.2136E-05" ixz="-0.00019406" iyy="0.40648" iyz="8.2679E-05" izz="0.52596" />
    </inertial>
    <visual>
      <origin xyz="0 0 0.03" />
      <geometry>
        <cylinder length="0.06" radius="0.04"/>
      </geometry>
    </visual>
  </link>
  <joint name="Lidar_Joint" type="fixed">
    <origin xyz="0.31 0 0.079" />
    <parent link="urdf_link" />
    <child link="Lidar" />
  </joint>
</robot>